multiprocessing.pool.RemoteTraceback: 
"""
Traceback (most recent call last):
  File "/usr/lib64/python3.6/multiprocessing/pool.py", line 119, in worker
    result = (True, func(*args, **kwds))
  File "/usr/lib64/python3.6/multiprocessing/pool.py", line 47, in starmapstar
    return list(itertools.starmap(args[0], args[1]))
  File "parallel_ins.py", line 219, in parallelize
    query_array.append(convert_dict_to_query(i))
  File "parallel_ins.py", line 194, in convert_dict_to_query
    query = (int(dic['PMID']), dic['journal_ISSN'], ','.join(dic['grants']), ','.join(dic['chemical']),
TypeError: sequence item 0: expected str instance, NoneType found
"""

The above exception was the direct cause of the following exception:

Traceback (most recent call last):
  File "parallel_ins.py", line 255, in <module>
    results = pool.starmap(parallelize, lst)
  File "/usr/lib64/python3.6/multiprocessing/pool.py", line 274, in starmap
    return self._map_async(func, iterable, starmapstar, chunksize).get()
  File "/usr/lib64/python3.6/multiprocessing/pool.py", line 644, in get
    raise self._value
TypeError: sequence item 0: expected str instance, NoneType found
